<robot name="r2d2">
 
 <material name="blue">
  <color rgba="0 0 0.8 1"/>
 </material>
 <material name="white">
  <color rgba="1 1 1 1"/>
 </material>
 <material name="black">
  <color rgba="0 0 0 1"/>
 </material>

 <link name="fixed_base">
  <visual>
   <geometry>
    <box size="0.6 0.6 0.1"/>
   </geometry> 
   <origin xyz="0 0 0.05"/>
   <material name="black"/>
  </visual>
 </link>

 <link name="link_1">
  <visual>
   <geometry>
    <cylinder length="0.6" radius="0.1"/>
   </geometry>
   <origin xyz="0 0 0.3"/>
   <material name="white"/>
  </visual>
 </link>

 <link name="link_2">
  <visual>
   <geometry>
    <cylinder length="0.6" radius="0.1"/>
   </geometry>
   <origin xyz="0 0 0.3"/>
   <material name="blue"/>
  </visual>
 </link>

 <joint name="joint_1" type="revolute">
  <parent link="fixed_base"/>
  <child link="link_1"/>
  <origin xyz="0 0 0.1"/>
  <axis xyz="1 0 0"/>
  <limit lower="-0.785" upper="0.785"/>
 </joint>
 
 <joint name="joint_2" type="revolute">
  <parent link="link_1"/>
  <child link="link_2"/>
  <origin xyz="0 0 0.6"/>
  <axis xyz="1 0 0"/>
  <limit lower="-0.785" upper="0.785"/>
 </joint>

</robot>
